<sdf version='1.7'>
  <world name='default'>
    <model name='ground_plane'>
      <static>1</static>
      <link name='link'>
        <collision name='collision'>
          <geometry>
            <plane>
              <normal>0 0 1</normal>
              <size>100 100</size>
            </plane>
          </geometry>
          <surface>
            <contact>
              <collide_bitmask>65535</collide_bitmask>
              <ode/>
            </contact>
            <friction>
              <ode>
                <mu>100</mu>
                <mu2>50</mu2>
              </ode>
              <torsional>
                <ode/>
              </torsional>
            </friction>
            <bounce/>
          </surface>
          <max_contacts>10</max_contacts>
        </collision>
        <visual name='visual'>
          <cast_shadows>0</cast_shadows>
          <geometry>
            <plane>
              <normal>0 0 1</normal>
              <size>100 100</size>
            </plane>
          </geometry>
          <material>
            <script>
              <uri>file://media/materials/scripts/gazebo.material</uri>
              <name>Gazebo/Grey</name>
            </script>
          </material>
        </visual>
        <self_collide>0</self_collide>
        <enable_wind>0</enable_wind>
        <kinematic>0</kinematic>
      </link>
    </model>
    <light name='sun' type='directional'>
      <cast_shadows>1</cast_shadows>
      <pose>0 0 10 0 -0 0</pose>
      <diffuse>0.8 0.8 0.8 1</diffuse>
      <specular>0.2 0.2 0.2 1</specular>
      <attenuation>
        <range>1000</range>
        <constant>0.9</constant>
        <linear>0.01</linear>
        <quadratic>0.001</quadratic>
      </attenuation>
      <direction>-0.5 0.1 -0.9</direction>
      <spot>
        <inner_angle>0</inner_angle>
        <outer_angle>0</outer_angle>
        <falloff>0</falloff>
      </spot>
    </light>
    <model name='my_mesh'>
      <pose>0 0 0 0 -0 0</pose>
      <static>1</static>
      <link name='body'>
        <visual name='visual'>
          <geometry>
            <mesh>
              <uri>file:///home/ideapad/Documents/plant_ground.dae</uri>
            </mesh>
          </geometry>
        </visual>
        <self_collide>0</self_collide>
        <enable_wind>0</enable_wind>
        <kinematic>0</kinematic>
      </link>
    </model>
    <gravity>0 0 -9.8</gravity>
    <magnetic_field>6e-06 2.3e-05 -4.2e-05</magnetic_field>
    <atmosphere type='adiabatic'/>
    <physics type='ode'>
      <max_step_size>0.001</max_step_size>
      <real_time_factor>1</real_time_factor>
      <real_time_update_rate>1000</real_time_update_rate>
    </physics>
    <scene>
      <ambient>0.4 0.4 0.4 1</ambient>
      <background>0.7 0.7 0.7 1</background>
      <shadows>1</shadows>
    </scene>
    <audio>
      <device>default</device>
    </audio>
    <wind/>
    <spherical_coordinates>
      <surface_model>EARTH_WGS84</surface_model>
      <latitude_deg>0</latitude_deg>
      <longitude_deg>0</longitude_deg>
      <elevation>0</elevation>
      <heading_deg>0</heading_deg>
    </spherical_coordinates>
    <model name='my_bot'>
      <link name='base_link'>
        <inertial>
          <pose>0.025283 0 0.054167 0 -0 0</pose>
          <mass>1.2</mass>
          <inertia>
            <ixx>0.102176</ixx>
            <ixy>0</ixy>
            <ixz>-0.00744158</ixz>
            <iyy>0.143212</iyy>
            <iyz>0</iyz>
            <izz>0.20786</izz>
          </inertia>
        </inertial>
        <collision name='base_link_fixed_joint_lump__chassis_collision'>
          <pose>0 0 0 0 -0 0</pose>
          <geometry>
            <box>
              <size>1 0.5 0.1</size>
            </box>
          </geometry>
          <surface>
            <contact>
              <ode/>
            </contact>
            <friction>
              <ode/>
              <torsional>
                <ode/>
              </torsional>
            </friction>
            <bounce/>
          </surface>
          <max_contacts>10</max_contacts>
        </collision>
        <collision name='base_link_fixed_joint_lump__chassis_top_collision_1'>
          <pose>0 0 0 0 -0 0</pose>
          <geometry>
            <box>
              <size>1 0.5 0.1</size>
            </box>
          </geometry>
          <surface>
            <contact>
              <ode/>
            </contact>
            <friction>
              <ode/>
              <torsional>
                <ode/>
              </torsional>
            </friction>
            <bounce/>
          </surface>
          <max_contacts>10</max_contacts>
        </collision>
        <visual name='base_link_fixed_joint_lump__chassis_visual'>
          <pose>0 0 -0.075 0 -0 0</pose>
          <geometry>
            <mesh>
              <scale>1 1 1</scale>
              <uri>/home/ideapad/develop/roboweed_ws/install/articubot_one/share/articubot_one/description/mesh/blender_top.stl</uri>
            </mesh>
          </geometry>
          <material>
            <script>
              <name>Gazebo/Orange</name>
              <uri>file://media/materials/scripts/gazebo.material</uri>
            </script>
          </material>
        </visual>
        <visual name='base_link_fixed_joint_lump__front_depth_camera_visual_1'>
          <pose>0.625 0 0.43 0 0.96 0</pose>
          <geometry>
            <box>
              <size>0.01 0.06 0.03</size>
            </box>
          </geometry>
          <material>
            <script>
              <name>Gazebo/Red</name>
              <uri>file://media/materials/scripts/gazebo.material</uri>
            </script>
          </material>
        </visual>
        <visual name='base_link_fixed_joint_lump__imu_link_visual_2'>
          <pose>0.2034 0 0.25 0 0 -1.57079</pose>
          <geometry>
            <box>
              <size>0.03 0.03 0.02</size>
            </box>
          </geometry>
        </visual>
        <visual name='base_link_fixed_joint_lump__laser_frame_visual_3'>
          <pose>0.1 0 0.4 0 -0 0</pose>
          <geometry>
            <cylinder>
              <length>0.04</length>
              <radius>0.025</radius>
            </cylinder>
          </geometry>
          <material>
            <script>
              <name>Gazebo/Black</name>
              <uri>file://media/materials/scripts/gazebo.material</uri>
            </script>
          </material>
        </visual>
        <visual name='base_link_fixed_joint_lump__rear_depth_camera_visual_4'>
          <pose>-0.645 0 0.43 -0 0.4 3.14159</pose>
          <geometry>
            <box>
              <size>0.01 0.06 0.03</size>
            </box>
          </geometry>
          <material>
            <script>
              <name>Gazebo/Red</name>
              <uri>file://media/materials/scripts/gazebo.material</uri>
            </script>
          </material>
        </visual>
        <visual name='base_link_fixed_joint_lump__chassis_top_visual_5'>
          <pose>0 0 -0.075 0 -0 0</pose>
          <geometry>
            <mesh>
              <scale>1 1 1</scale>
              <uri>/home/ideapad/develop/roboweed_ws/install/articubot_one/share/articubot_one/description/mesh/blender_body.stl</uri>
            </mesh>
          </geometry>
          <material>
            <script>
              <name>Gazebo/Red</name>
              <uri>file://media/materials/scripts/gazebo.material</uri>
            </script>
          </material>
        </visual>
        <sensor name='front_depth_camera' type='depth'>
          <visualize>1</visualize>
          <update_rate>10</update_rate>
          <plugin name='front_depth_camera_controller' filename='libgazebo_ros_camera.so'>
            <frame_name>front_depth_camera_optical</frame_name>
            <min_depth>0.1</min_depth>
            <max_depth>100.0</max_depth>
          </plugin>
          <pose>0.625 0 0.43 0 0.96 0</pose>
          <camera>
            <horizontal_fov>1.047</horizontal_fov>
            <image>
              <width>320</width>
              <height>240</height>
            </image>
            <clip>
              <near>0.1</near>
              <far>100</far>
            </clip>
          </camera>
          <front_depth_camera>
            <horizontal_fov>0.8</horizontal_fov>
            <image>
              <format>B8G8R8</format>
              <width>640</width>
              <height>480</height>
            </image>
            <clip>
              <near>0.05</near>
              <far>8.0</far>
            </clip>
          </front_depth_camera>
        </sensor>
        <gravity>1</gravity>
        <sensor name='imu_sensor' type='imu'>
          <always_on>1</always_on>
          <update_rate>100</update_rate>
          <visualize>1</visualize>
          <topic>__default_topic__</topic>
          <plugin name='imu' filename='libgazebo_ros_imu_sensor.so'>
            <topicName>imu</topicName>
            <bodyName>imu_link</bodyName>
            <updateRateHZ>10.0</updateRateHZ>
            <gaussianNoise>0.0</gaussianNoise>
            <xyzOffset>0 0 0</xyzOffset>
            <rpyOffset>0 0 0</rpyOffset>
            <frameName>imu_link</frameName>
            <initialOrientationAsReference>0</initialOrientationAsReference>
          </plugin>
          <pose>0.2034 0 0.25 0 0 -1.57079</pose>
          <imu/>
        </sensor>
        <sensor name='laser' type='ray'>
          <visualize>0</visualize>
          <update_rate>10</update_rate>
          <ray>
            <scan>
              <horizontal>
                <samples>360</samples>
                <min_angle>-3.14</min_angle>
                <max_angle>3.14</max_angle>
                <resolution>1</resolution>
              </horizontal>
              <vertical>
                <samples>1</samples>
                <min_angle>0</min_angle>
                <max_angle>0</max_angle>
              </vertical>
            </scan>
            <range>
              <min>0.17</min>
              <max>40</max>
            </range>
          </ray>
          <plugin name='laser' filename='libgazebo_ros_ray_sensor.so'>
            <ros>
              <argument>~/out:=scan</argument>
            </ros>
            <output_type>sensor_msgs/LaserScan</output_type>
            <frame_name>laser_frame</frame_name>
          </plugin>
          <pose>0.1 0 0.4 0 -0 0</pose>
        </sensor>
        <sensor name='rear_depth_camera' type='depth'>
          <visualize>1</visualize>
          <update_rate>10</update_rate>
          <plugin name='rear_depth_camera_controller' filename='libgazebo_ros_camera.so'>
            <frame_name>rear_depth_camera_optical</frame_name>
            <min_depth>0.1</min_depth>
            <max_depth>100.0</max_depth>
          </plugin>
          <pose>-0.645 0 0.43 -0 0.4 3.14159</pose>
          <camera>
            <horizontal_fov>1.047</horizontal_fov>
            <image>
              <width>320</width>
              <height>240</height>
            </image>
            <clip>
              <near>0.1</near>
              <far>100</far>
            </clip>
          </camera>
          <rear_depth_camera>
            <horizontal_fov>1.089</horizontal_fov>
            <image>
              <format>B8G8R8</format>
              <width>640</width>
              <height>480</height>
            </image>
            <clip>
              <near>0.05</near>
              <far>8.0</far>
            </clip>
          </rear_depth_camera>
        </sensor>
        <self_collide>0</self_collide>
        <enable_wind>0</enable_wind>
        <kinematic>0</kinematic>
      </link>
      <joint name='front_left_wheel_joint' type='revolute'>
        <pose relative_to='base_link'>0.325 0.535 0 -1.5708 0 0</pose>
        <parent>base_link</parent>
        <child>front_left_wheel</child>
        <axis>
          <xyz>0 0 1</xyz>
          <limit>
            <lower>-1e+16</lower>
            <upper>1e+16</upper>
          </limit>
          <dynamics>
            <spring_reference>0</spring_reference>
            <spring_stiffness>0</spring_stiffness>
          </dynamics>
        </axis>
      </joint>
      <link name='front_left_wheel'>
        <pose relative_to='front_left_wheel_joint'>0 0 0 0 -0 0</pose>
        <inertial>
          <pose>0 0 0 0 -0 0</pose>
          <mass>1</mass>
          <inertia>
            <ixx>0.0103</ixx>
            <ixy>0</ixy>
            <ixz>0</ixz>
            <iyy>0.0103</iyy>
            <iyz>0</iyz>
            <izz>0.02</izz>
          </inertia>
        </inertial>
        <collision name='front_left_wheel_collision'>
          <pose>0 0 0 0 -0 0</pose>
          <geometry>
            <cylinder>
              <length>0.06</length>
              <radius>0.2</radius>
            </cylinder>
          </geometry>
          <surface>
            <contact>
              <ode/>
            </contact>
            <friction>
              <ode>
                <mu>10</mu>
                <mu2>10</mu2>
              </ode>
              <torsional>
                <ode/>
              </torsional>
            </friction>
            <bounce/>
          </surface>
          <max_contacts>10</max_contacts>
        </collision>
        <visual name='front_left_wheel_visual'>
          <pose>0 0 0 3.14159 -0 3.14159</pose>
          <geometry>
            <mesh>
              <scale>1 1 1</scale>
              <uri>/home/ideapad/develop/roboweed_ws/install/articubot_one/share/articubot_one/description/mesh/blender_wheel.stl</uri>
            </mesh>
          </geometry>
          <material>
            <script>
              <name>Gazebo/Blue</name>
              <uri>file://media/materials/scripts/gazebo.material</uri>
            </script>
          </material>
        </visual>
        <self_collide>0</self_collide>
        <enable_wind>0</enable_wind>
        <kinematic>0</kinematic>
      </link>
      <joint name='front_right_wheel_joint' type='revolute'>
        <pose relative_to='base_link'>0.325 -0.535 0 1.5708 -0 0</pose>
        <parent>base_link</parent>
        <child>front_right_wheel</child>
        <axis>
          <xyz>0 0 -1</xyz>
          <limit>
            <lower>-1e+16</lower>
            <upper>1e+16</upper>
          </limit>
          <dynamics>
            <spring_reference>0</spring_reference>
            <spring_stiffness>0</spring_stiffness>
          </dynamics>
        </axis>
      </joint>
      <link name='front_right_wheel'>
        <pose relative_to='front_right_wheel_joint'>0 0 0 0 -0 0</pose>
        <inertial>
          <pose>0 0 0 0 -0 0</pose>
          <mass>1</mass>
          <inertia>
            <ixx>0.0103</ixx>
            <ixy>0</ixy>
            <ixz>0</ixz>
            <iyy>0.0103</iyy>
            <iyz>0</iyz>
            <izz>0.02</izz>
          </inertia>
        </inertial>
        <collision name='front_right_wheel_collision'>
          <pose>0 0 0 0 -0 0</pose>
          <geometry>
            <cylinder>
              <length>0.06</length>
              <radius>0.2</radius>
            </cylinder>
          </geometry>
          <surface>
            <contact>
              <ode/>
            </contact>
            <friction>
              <ode>
                <mu>10</mu>
                <mu2>10</mu2>
              </ode>
              <torsional>
                <ode/>
              </torsional>
            </friction>
            <bounce/>
          </surface>
          <max_contacts>10</max_contacts>
        </collision>
        <visual name='front_right_wheel_visual'>
          <pose>0 0 0 3.14159 -0 3.14159</pose>
          <geometry>
            <mesh>
              <scale>1 1 1</scale>
              <uri>/home/ideapad/develop/roboweed_ws/install/articubot_one/share/articubot_one/description/mesh/blender_wheel.stl</uri>
            </mesh>
          </geometry>
          <material>
            <script>
              <name>Gazebo/Blue</name>
              <uri>file://media/materials/scripts/gazebo.material</uri>
            </script>
          </material>
        </visual>
        <self_collide>0</self_collide>
        <enable_wind>0</enable_wind>
        <kinematic>0</kinematic>
      </link>
      <joint name='rear_left_wheel_joint' type='revolute'>
        <pose relative_to='base_link'>-0.325 0.535 0 -1.5708 0 0</pose>
        <parent>base_link</parent>
        <child>rear_left_wheel</child>
        <axis>
          <xyz>0 0 1</xyz>
          <limit>
            <lower>-1e+16</lower>
            <upper>1e+16</upper>
          </limit>
          <dynamics>
            <spring_reference>0</spring_reference>
            <spring_stiffness>0</spring_stiffness>
          </dynamics>
        </axis>
      </joint>
      <link name='rear_left_wheel'>
        <pose relative_to='rear_left_wheel_joint'>0 0 0 0 -0 0</pose>
        <inertial>
          <pose>0 0 0 0 -0 0</pose>
          <mass>1</mass>
          <inertia>
            <ixx>0.0103</ixx>
            <ixy>0</ixy>
            <ixz>0</ixz>
            <iyy>0.0103</iyy>
            <iyz>0</iyz>
            <izz>0.02</izz>
          </inertia>
        </inertial>
        <collision name='rear_left_wheel_collision'>
          <pose>0 0 0 0 -0 0</pose>
          <geometry>
            <cylinder>
              <length>0.06</length>
              <radius>0.2</radius>
            </cylinder>
          </geometry>
          <surface>
            <contact>
              <ode/>
            </contact>
            <friction>
              <ode>
                <mu>10</mu>
                <mu2>10</mu2>
              </ode>
              <torsional>
                <ode/>
              </torsional>
            </friction>
            <bounce/>
          </surface>
          <max_contacts>10</max_contacts>
        </collision>
        <visual name='rear_left_wheel_visual'>
          <pose>0 0 0 3.14159 -0 3.14159</pose>
          <geometry>
            <mesh>
              <scale>1 1 1</scale>
              <uri>/home/ideapad/develop/roboweed_ws/install/articubot_one/share/articubot_one/description/mesh/blender_wheel.stl</uri>
            </mesh>
          </geometry>
          <material>
            <script>
              <name>Gazebo/Blue</name>
              <uri>file://media/materials/scripts/gazebo.material</uri>
            </script>
          </material>
        </visual>
        <self_collide>0</self_collide>
        <enable_wind>0</enable_wind>
        <kinematic>0</kinematic>
      </link>
      <joint name='rear_right_wheel_joint' type='revolute'>
        <pose relative_to='base_link'>-0.325 -0.535 0 1.5708 -0 0</pose>
        <parent>base_link</parent>
        <child>rear_right_wheel</child>
        <axis>
          <xyz>0 0 -1</xyz>
          <limit>
            <lower>-1e+16</lower>
            <upper>1e+16</upper>
          </limit>
          <dynamics>
            <spring_reference>0</spring_reference>
            <spring_stiffness>0</spring_stiffness>
          </dynamics>
        </axis>
      </joint>
      <link name='rear_right_wheel'>
        <pose relative_to='rear_right_wheel_joint'>0 0 0 0 -0 0</pose>
        <inertial>
          <pose>0 0 0 0 -0 0</pose>
          <mass>1</mass>
          <inertia>
            <ixx>0.0103</ixx>
            <ixy>0</ixy>
            <ixz>0</ixz>
            <iyy>0.0103</iyy>
            <iyz>0</iyz>
            <izz>0.02</izz>
          </inertia>
        </inertial>
        <collision name='rear_right_wheel_collision'>
          <pose>0 0 0 0 -0 0</pose>
          <geometry>
            <cylinder>
              <length>0.06</length>
              <radius>0.2</radius>
            </cylinder>
          </geometry>
          <surface>
            <contact>
              <ode/>
            </contact>
            <friction>
              <ode>
                <mu>10</mu>
                <mu2>10</mu2>
              </ode>
              <torsional>
                <ode/>
              </torsional>
            </friction>
            <bounce/>
          </surface>
          <max_contacts>10</max_contacts>
        </collision>
        <visual name='rear_right_wheel_visual'>
          <pose>0 0 0 3.14159 -0 3.14159</pose>
          <geometry>
            <mesh>
              <scale>1 1 1</scale>
              <uri>/home/ideapad/develop/roboweed_ws/install/articubot_one/share/articubot_one/description/mesh/blender_wheel.stl</uri>
            </mesh>
          </geometry>
          <material>
            <script>
              <name>Gazebo/Blue</name>
              <uri>file://media/materials/scripts/gazebo.material</uri>
            </script>
          </material>
        </visual>
        <self_collide>0</self_collide>
        <enable_wind>0</enable_wind>
        <kinematic>0</kinematic>
      </link>
      <static>0</static>
      <plugin name='gazebo_ros2_control' filename='libgazebo_ros2_control.so'>
        <parameters>/home/ideapad/develop/roboweed_ws/install/articubot_one/share/articubot_one/config/my_controllers.yaml</parameters>
        <parameters>/home/ideapad/develop/roboweed_ws/install/articubot_one/share/articubot_one/config/gaz_ros2_ctl_use_sim.yaml</parameters>
      </plugin>
      <pose>0 0 1 0 -0 0</pose>
    </model>
    <model name='my_mesh_clone'>
      <pose>0.016801 -5.83927 0 0 0 -1.57077</pose>
      <static>1</static>
      <link name='body'>
        <visual name='visual'>
          <geometry>
            <mesh>
              <uri>file:///home/ideapad/Documents/plant_ground.dae</uri>
            </mesh>
          </geometry>
        </visual>
        <self_collide>0</self_collide>
        <enable_wind>0</enable_wind>
        <kinematic>0</kinematic>
      </link>
    </model>
    <model name='my_mesh_clone_clone'>
      <pose>-0.049166 3.76083 0 0 0 -1.57077</pose>
      <static>1</static>
      <link name='body'>
        <visual name='visual'>
          <geometry>
            <mesh>
              <uri>file:///home/ideapad/Documents/plant_ground.dae</uri>
            </mesh>
          </geometry>
        </visual>
        <self_collide>0</self_collide>
        <enable_wind>0</enable_wind>
        <kinematic>0</kinematic>
      </link>
    </model>
    <model name='my_mesh_clone_clone_0'>
      <pose>4.97677 -0.821447 0 0 0 -1.57077</pose>
      <static>1</static>
      <link name='body'>
        <visual name='visual'>
          <geometry>
            <mesh>
              <uri>file:///home/ideapad/Documents/plant_ground.dae</uri>
            </mesh>
          </geometry>
        </visual>
        <self_collide>0</self_collide>
        <enable_wind>0</enable_wind>
        <kinematic>0</kinematic>
      </link>
    </model>
    <model name='my_mesh_clone_clone_1'>
      <pose>4.90497 3.75903 0 0 0 -1.57077</pose>
      <static>1</static>
      <link name='body'>
        <visual name='visual'>
          <geometry>
            <mesh>
              <uri>file:///home/ideapad/Documents/plant_ground.dae</uri>
            </mesh>
          </geometry>
        </visual>
        <self_collide>0</self_collide>
        <enable_wind>0</enable_wind>
        <kinematic>0</kinematic>
      </link>
    </model>
    <model name='my_mesh_clone_clone_2'>
      <pose>-4.9238 -0.868713 0 0 0 -1.57077</pose>
      <static>1</static>
      <link name='body'>
        <visual name='visual'>
          <geometry>
            <mesh>
              <uri>file:///home/ideapad/Documents/plant_ground.dae</uri>
            </mesh>
          </geometry>
        </visual>
        <self_collide>0</self_collide>
        <enable_wind>0</enable_wind>
        <kinematic>0</kinematic>
      </link>
    </model>
    <model name='my_mesh_clone_clone_3'>
      <pose>-4.85061 3.67916 0 0 0 -1.57077</pose>
      <static>1</static>
      <link name='body'>
        <visual name='visual'>
          <geometry>
            <mesh>
              <uri>file:///home/ideapad/Documents/plant_ground.dae</uri>
            </mesh>
          </geometry>
        </visual>
        <self_collide>0</self_collide>
        <enable_wind>0</enable_wind>
        <kinematic>0</kinematic>
      </link>
    </model>
    <model name='my_mesh_clone_clone_4'>
      <pose>-4.58424 -5.80896 0 0 0 -1.57077</pose>
      <static>1</static>
      <link name='body'>
        <visual name='visual'>
          <geometry>
            <mesh>
              <uri>file:///home/ideapad/Documents/plant_ground.dae</uri>
            </mesh>
          </geometry>
        </visual>
        <self_collide>0</self_collide>
        <enable_wind>0</enable_wind>
        <kinematic>0</kinematic>
      </link>
    </model>
    <model name='my_mesh_clone_clone_5'>
      <pose>4.88651 -5.91764 0 0 0 -1.57077</pose>
      <static>1</static>
      <link name='body'>
        <visual name='visual'>
          <geometry>
            <mesh>
              <uri>file:///home/ideapad/Documents/plant_ground.dae</uri>
            </mesh>
          </geometry>
        </visual>
        <self_collide>0</self_collide>
        <enable_wind>0</enable_wind>
        <kinematic>0</kinematic>
      </link>
    </model>
    <model name='my_mesh_clone_clone_0_clone'>
      <pose>9.85638 -0.825943 0 0 0 -1.57077</pose>
      <static>1</static>
      <link name='body'>
        <visual name='visual'>
          <geometry>
            <mesh>
              <uri>file:///home/ideapad/Documents/plant_ground.dae</uri>
            </mesh>
          </geometry>
        </visual>
        <self_collide>0</self_collide>
        <enable_wind>0</enable_wind>
        <kinematic>0</kinematic>
      </link>
    </model>
    <model name='my_mesh_clone_clone_0_clone_0'>
      <pose>9.8101 3.79479 0 0 0 -1.57077</pose>
      <static>1</static>
      <link name='body'>
        <visual name='visual'>
          <geometry>
            <mesh>
              <uri>file:///home/ideapad/Documents/plant_ground.dae</uri>
            </mesh>
          </geometry>
        </visual>
        <self_collide>0</self_collide>
        <enable_wind>0</enable_wind>
        <kinematic>0</kinematic>
      </link>
    </model>
    <model name='my_mesh_clone_clone_0_clone_1'>
      <pose>9.7889 -5.72113 0 0 0 -1.57077</pose>
      <static>1</static>
      <link name='body'>
        <visual name='visual'>
          <geometry>
            <mesh>
              <uri>file:///home/ideapad/Documents/plant_ground.dae</uri>
            </mesh>
          </geometry>
        </visual>
        <self_collide>0</self_collide>
        <enable_wind>0</enable_wind>
        <kinematic>0</kinematic>
      </link>
    </model>
    <model name='my_mesh_clone_clone_0_clone_2'>
      <pose>-9.04625 -5.93157 0 0 0 -1.57077</pose>
      <static>1</static>
      <link name='body'>
        <visual name='visual'>
          <geometry>
            <mesh>
              <uri>file:///home/ideapad/Documents/plant_ground.dae</uri>
            </mesh>
          </geometry>
        </visual>
        <self_collide>0</self_collide>
        <enable_wind>0</enable_wind>
        <kinematic>0</kinematic>
      </link>
    </model>
    <model name='my_mesh_clone_clone_0_clone_3'>
      <pose>-9.26308 -0.864641 0 0 0 -1.57077</pose>
      <static>1</static>
      <link name='body'>
        <visual name='visual'>
          <geometry>
            <mesh>
              <uri>file:///home/ideapad/Documents/plant_ground.dae</uri>
            </mesh>
          </geometry>
        </visual>
        <self_collide>0</self_collide>
        <enable_wind>0</enable_wind>
        <kinematic>0</kinematic>
      </link>
    </model>
    <model name='my_mesh_clone_clone_0_clone_4'>
      <pose>-9.39458 3.73678 0 0 0 -1.57077</pose>
      <static>1</static>
      <link name='body'>
        <visual name='visual'>
          <geometry>
            <mesh>
              <uri>file:///home/ideapad/Documents/plant_ground.dae</uri>
            </mesh>
          </geometry>
        </visual>
        <self_collide>0</self_collide>
        <enable_wind>0</enable_wind>
        <kinematic>0</kinematic>
      </link>
    </model>
    <state world_name='default'>
      <sim_time>127 688000000</sim_time>
      <real_time>129 988819184</real_time>
      <wall_time>1695288891 530523592</wall_time>
      <iterations>127688</iterations>
      <model name='ground_plane'>
        <pose>0 0 0 0 -0 0</pose>
        <scale>1 1 1</scale>
        <link name='link'>
          <pose>0 0 0 0 -0 0</pose>
          <velocity>0 0 0 0 -0 0</velocity>
          <acceleration>0 0 0 0 -0 0</acceleration>
          <wrench>0 0 0 0 -0 0</wrench>
        </link>
      </model>
      <model name='my_bot'>
        <pose>0.000317 -0.000896 0.199998 -4e-06 -0 4e-06</pose>
        <scale>1 1 1</scale>
        <link name='base_link'>
          <pose>0.000317 -0.000896 0.199998 -4e-06 -0 4e-06</pose>
          <velocity>7e-06 0.000854 -0.002566 -0.004545 4e-06 -2.5e-05</velocity>
          <acceleration>0.00268 2.2137 -5.13293 -2.80679 0.00769 -0.048998</acceleration>
          <wrench>0.003216 2.65644 -6.15951 0 -0 0</wrench>
        </link>
        <link name='front_left_wheel'>
          <pose>0.325314 0.534105 0.199995 -1.57081 -0.008301 4e-06</pose>
          <velocity>3.1e-05 0.000888 -0.004969 -0.004512 -4e-06 -2.1e-05</velocity>
          <acceleration>0.039137 1.74857 -9.9679 -2.77381 -3.6e-05 -0.08916</acceleration>
          <wrench>0.039137 1.74857 -9.9679 0 -0 0</wrench>
        </link>
        <link name='front_right_wheel'>
          <pose>0.325319 -0.535894 0.2 1.57081 0.001604 4e-06</pose>
          <velocity>-1.3e-05 0.000845 -0.000145 -0.004263 -7.3e-05 -4.6e-05</velocity>
          <acceleration>-0.031003 1.70498 -0.281013 -2.52442 -0.035787 -0.137433</acceleration>
          <wrench>-0.031003 1.70498 -0.281013 0 -0 0</wrench>
        </link>
        <link name='rear_left_wheel'>
          <pose>-0.324685 0.534103 0.199995 -1.5708 0.001013 4e-06</pose>
          <velocity>1.4e-05 0.000897 -0.004973 -0.004556 -4e-06 -3.1e-05</velocity>
          <acceleration>0.02274 1.7733 -9.96943 -2.81774 -3.6e-05 -0.107634</acceleration>
          <wrench>0.02274 1.7733 -9.96943 0 -0 0</wrench>
        </link>
        <link name='rear_right_wheel'>
          <pose>-0.324681 -0.535897 0.2 1.57081 0.005684 4e-06</pose>
          <velocity>-6e-06 0.000856 -0.000143 -0.004318 -3.4e-05 -1.2e-05</velocity>
          <acceleration>-0.024178 1.73214 -0.276335 -2.57975 -0.015525 -0.070882</acceleration>
          <wrench>-0.024178 1.73214 -0.276335 0 -0 0</wrench>
        </link>
      </model>
      <model name='my_mesh'>
        <pose>0.005027 -0.836988 0 0 0 -1.57077</pose>
        <scale>1 1 1</scale>
        <link name='body'>
          <pose>0.005027 -0.836988 0 0 0 -1.57077</pose>
          <velocity>0 0 0 0 -0 0</velocity>
          <acceleration>0 0 0 0 -0 0</acceleration>
          <wrench>0 0 0 0 -0 0</wrench>
        </link>
      </model>
      <model name='my_mesh_clone'>
        <pose>0.016801 -5.83927 0 0 0 -1.57077</pose>
        <scale>1 1 1</scale>
        <link name='body'>
          <pose>0.016801 -5.83927 0 0 0 -1.57077</pose>
          <velocity>0 0 0 0 -0 0</velocity>
          <acceleration>0 0 0 0 -0 0</acceleration>
          <wrench>0 0 0 0 -0 0</wrench>
        </link>
      </model>
      <model name='my_mesh_clone_clone'>
        <pose>-0.049166 3.76083 0 0 0 -1.57077</pose>
        <scale>1 1 1</scale>
        <link name='body'>
          <pose>-0.049166 3.76083 0 0 0 -1.57077</pose>
          <velocity>0 0 0 0 -0 0</velocity>
          <acceleration>0 0 0 0 -0 0</acceleration>
          <wrench>0 0 0 0 -0 0</wrench>
        </link>
      </model>
      <model name='my_mesh_clone_clone_0'>
        <pose>4.97677 -0.821447 0 0 0 -1.57077</pose>
        <scale>1 1 1</scale>
        <link name='body'>
          <pose>4.97677 -0.821447 0 0 0 -1.57077</pose>
          <velocity>0 0 0 0 -0 0</velocity>
          <acceleration>0 0 0 0 -0 0</acceleration>
          <wrench>0 0 0 0 -0 0</wrench>
        </link>
      </model>
      <model name='my_mesh_clone_clone_0_clone'>
        <pose>9.85638 -0.825943 0 0 0 -1.57077</pose>
        <scale>1 1 1</scale>
        <link name='body'>
          <pose>9.85638 -0.825943 0 0 0 -1.57077</pose>
          <velocity>0 0 0 0 -0 0</velocity>
          <acceleration>0 0 0 0 -0 0</acceleration>
          <wrench>0 0 0 0 -0 0</wrench>
        </link>
      </model>
      <model name='my_mesh_clone_clone_0_clone_0'>
        <pose>9.8101 3.79479 0 0 0 -1.57077</pose>
        <scale>1 1 1</scale>
        <link name='body'>
          <pose>9.8101 3.79479 0 0 0 -1.57077</pose>
          <velocity>0 0 0 0 -0 0</velocity>
          <acceleration>0 0 0 0 -0 0</acceleration>
          <wrench>0 0 0 0 -0 0</wrench>
        </link>
      </model>
      <model name='my_mesh_clone_clone_0_clone_1'>
        <pose>9.7889 -5.72113 0 0 0 -1.57077</pose>
        <scale>1 1 1</scale>
        <link name='body'>
          <pose>9.7889 -5.72113 0 0 0 -1.57077</pose>
          <velocity>0 0 0 0 -0 0</velocity>
          <acceleration>0 0 0 0 -0 0</acceleration>
          <wrench>0 0 0 0 -0 0</wrench>
        </link>
      </model>
      <model name='my_mesh_clone_clone_0_clone_2'>
        <pose>-9.04626 -5.75948 0 0 0 -1.57077</pose>
        <scale>1 1 1</scale>
        <link name='body'>
          <pose>-9.04626 -5.75948 0 0 0 -1.57077</pose>
          <velocity>0 0 0 0 -0 0</velocity>
          <acceleration>0 0 0 0 -0 0</acceleration>
          <wrench>0 0 0 0 -0 0</wrench>
        </link>
      </model>
      <model name='my_mesh_clone_clone_0_clone_3'>
        <pose>-9.26308 -0.864641 0 0 0 -1.57077</pose>
        <scale>1 1 1</scale>
        <link name='body'>
          <pose>-9.26308 -0.864641 0 0 0 -1.57077</pose>
          <velocity>0 0 0 0 -0 0</velocity>
          <acceleration>0 0 0 0 -0 0</acceleration>
          <wrench>0 0 0 0 -0 0</wrench>
        </link>
      </model>
      <model name='my_mesh_clone_clone_0_clone_4'>
        <pose>-9.39458 3.73678 0 0 0 -1.57077</pose>
        <scale>1 1 1</scale>
        <link name='body'>
          <pose>-9.39458 3.73678 0 0 0 -1.57077</pose>
          <velocity>0 0 0 0 -0 0</velocity>
          <acceleration>0 0 0 0 -0 0</acceleration>
          <wrench>0 0 0 0 -0 0</wrench>
        </link>
      </model>
      <model name='my_mesh_clone_clone_1'>
        <pose>4.90497 3.75903 0 0 0 -1.57077</pose>
        <scale>1 1 1</scale>
        <link name='body'>
          <pose>4.90497 3.75903 0 0 0 -1.57077</pose>
          <velocity>0 0 0 0 -0 0</velocity>
          <acceleration>0 0 0 0 -0 0</acceleration>
          <wrench>0 0 0 0 -0 0</wrench>
        </link>
      </model>
      <model name='my_mesh_clone_clone_2'>
        <pose>-4.9238 -0.868713 0 0 0 -1.57077</pose>
        <scale>1 1 1</scale>
        <link name='body'>
          <pose>-4.9238 -0.868713 0 0 0 -1.57077</pose>
          <velocity>0 0 0 0 -0 0</velocity>
          <acceleration>0 0 0 0 -0 0</acceleration>
          <wrench>0 0 0 0 -0 0</wrench>
        </link>
      </model>
      <model name='my_mesh_clone_clone_3'>
        <pose>-4.85061 3.67916 0 0 0 -1.57077</pose>
        <scale>1 1 1</scale>
        <link name='body'>
          <pose>-4.85061 3.67916 0 0 0 -1.57077</pose>
          <velocity>0 0 0 0 -0 0</velocity>
          <acceleration>0 0 0 0 -0 0</acceleration>
          <wrench>0 0 0 0 -0 0</wrench>
        </link>
      </model>
      <model name='my_mesh_clone_clone_4'>
        <pose>-4.58424 -5.80896 0 0 0 -1.57077</pose>
        <scale>1 1 1</scale>
        <link name='body'>
          <pose>-4.58424 -5.80896 0 0 0 -1.57077</pose>
          <velocity>0 0 0 0 -0 0</velocity>
          <acceleration>0 0 0 0 -0 0</acceleration>
          <wrench>0 0 0 0 -0 0</wrench>
        </link>
      </model>
      <model name='my_mesh_clone_clone_5'>
        <pose>4.88651 -5.77442 0 0 0 -1.57077</pose>
        <scale>1 1 1</scale>
        <link name='body'>
          <pose>4.88651 -5.77442 0 0 0 -1.57077</pose>
          <velocity>0 0 0 0 -0 0</velocity>
          <acceleration>0 0 0 0 -0 0</acceleration>
          <wrench>0 0 0 0 -0 0</wrench>
        </link>
      </model>
      <light name='sun'>
        <pose>0 0 10 0 -0 0</pose>
      </light>
    </state>
    <gui fullscreen='0'>
      <camera name='user_camera'>
        <pose>11.0511 -16.3123 28.0943 0 0.999647 2.21219</pose>
        <view_controller>orbit</view_controller>
        <projection_type>perspective</projection_type>
      </camera>
    </gui>
  </world>
</sdf>
